<?xml version="1.0" ?>
<!-- =================================================================================== -->
<!-- |    This document was autogenerated by xacro from /home/kuwagata/catkin_ws/src/six_dof_cam/six_dof_cam_description/urdf/six_dof_cam.xacro | -->
<!-- |    EDITING THIS FILE BY HAND IS NOT RECOMMENDED                                 | -->
<!-- =================================================================================== -->
<robot name="six_dof_cam" xmlns:xacro="http://ros.org/wiki/xacro">
  <!-- =============== Link & Joint =============== -->
  <link name="world"/>
  <joint name="base_joint" type="fixed">
    <origin rpy="0 0 0" xyz="0 0 0"/>
    <parent link="world"/>
    <child link="base_link"/>
  </joint>
  <link name="base_link">
    <visual>
      <geometry>
        <box size="0.1 0.1 0.1"/>
      </geometry>
      <origin rpy="0 0 0" xyz="0.05 0 0.05"/>
    </visual>
    <collision>
      <geometry>
        <box size="0.1 0.1 0.1"/>
      </geometry>
      <origin rpy="0 0 0" xyz="0.05 0 0.05"/>
    </collision>
    <inertial>
      <origin rpy="0 0 0" xyz="0 0 0"/>
      <mass value="1.0"/>
      <inertia ixx="1.0" ixy="0.0" ixz="0.0" iyy="1.0" iyz="0.0" izz="1.0"/>
    </inertial>
  </link>
  <joint name="x_linear_actuator_joint" type="prismatic">
    <origin rpy="0 0 0" xyz="0 0 0"/>
    <axis xyz="1 0 0"/>
    <parent link="base_link"/>
    <child link="x_linear_actuator_link"/>
    <limit effort="1000.0" lower="-3" upper="3" velocity="100.0"/>
  </joint>
  <link name="x_linear_actuator_link">
    <inertial>
      <origin xyz="0 0 0"/>
      <mass value="1.0"/>
      <inertia ixx="1.0" ixy="0.0" ixz="0.0" iyy="1.0" iyz="0.0" izz="1.0"/>
    </inertial>
  </link>
  <joint name="y_linear_actuator_joint" type="prismatic">
    <origin rpy="0 0 0" xyz="0 0 0"/>
    <axis xyz="0 1 0"/>
    <parent link="x_linear_actuator_link"/>
    <child link="y_linear_actuator_link"/>
    <limit effort="1000.0" lower="-3" upper="3" velocity="100.0"/>
  </joint>
  <link name="y_linear_actuator_link">
    <inertial>
      <origin xyz="0 0 0"/>
      <mass value="1.0"/>
      <inertia ixx="1.0" ixy="0.0" ixz="0.0" iyy="1.0" iyz="0.0" izz="1.0"/>
    </inertial>
  </link>
  <joint name="z_linear_actuator_joint" type="prismatic">
    <origin rpy="0 0 0" xyz="0 0 0"/>
    <axis xyz="0 0 1"/>
    <parent link="y_linear_actuator_link"/>
    <child link="z_linear_actuator_link"/>
    <limit effort="1000.0" lower="-3" upper="3" velocity="100.0"/>
  </joint>
  <link name="z_linear_actuator_link">
    <inertial>
      <origin xyz="0 0 0"/>
      <mass value="1.0"/>
      <inertia ixx="1.0" ixy="0.0" ixz="0.0" iyy="1.0" iyz="0.0" izz="1.0"/>
    </inertial>
  </link>
  <joint name="x_rotary_actuator_joint" type="revolute">
    <origin rpy="0 0 0" xyz="0 0 0"/>
    <axis xyz="1 0 0"/>
    <parent link="z_linear_actuator_link"/>
    <child link="x_rotary_actuator_link"/>
    <limit effort="1000.0" lower="-3.14" upper="3.14" velocity="100.0"/>
  </joint>
  <link name="x_rotary_actuator_link">
    <inertial>
      <origin xyz="0 0 0"/>
      <mass value="1.0"/>
      <inertia ixx="1.0" ixy="0.0" ixz="0.0" iyy="1.0" iyz="0.0" izz="1.0"/>
    </inertial>
  </link>
  <joint name="y_rotary_actuator_joint" type="revolute">
    <origin rpy="0 0 0" xyz="0 0 0"/>
    <axis xyz="0 1 0"/>
    <parent link="x_rotary_actuator_link"/>
    <child link="y_rotary_actuator_link"/>
    <limit effort="1000.0" lower="-3.14" upper="3.14" velocity="100.0"/>
  </joint>
  <link name="y_rotary_actuator_link">
    <inertial>
      <origin xyz="0 0 0"/>
      <mass value="1.0"/>
      <inertia ixx="1.0" ixy="0.0" ixz="0.0" iyy="1.0" iyz="0.0" izz="1.0"/>
    </inertial>
  </link>
  <joint name="z_rotary_actuator_joint" type="revolute">
    <origin rpy="0 0 0" xyz="0 0 0"/>
    <axis xyz="0 0 1"/>
    <parent link="y_rotary_actuator_link"/>
    <child link="z_rotary_actuator_link"/>
    <limit effort="1000.0" lower="-3.14" upper="3.14" velocity="100.0"/>
  </joint>
  <link name="z_rotary_actuator_link">
    <inertial>
      <origin xyz="0 0 0"/>
      <mass value="1.0"/>
      <inertia ixx="1.0" ixy="0.0" ixz="0.0" iyy="1.0" iyz="0.0" izz="1.0"/>
    </inertial>
  </link>
  <joint name="camera_joint" type="fixed">
    <origin rpy="0 0 0" xyz="0 0 0"/>
    <parent link="z_rotary_actuator_link"/>
    <child link="camera_link"/>
  </joint>
  <link name="camera_link">
    <visual>
      <geometry>
        <box size="0.1 0.1 0.1"/>
      </geometry>
    </visual>
    <collision>
      <geometry>
        <box size="0.1 0.1 0.1"/>
      </geometry>
    </collision>
    <inertial>
      <origin rpy="0 0 0" xyz="0 0 0"/>
      <mass value="0.01"/>
      <inertia ixx="0.01" ixy="0.0" ixz="0.0" iyy="0.01" iyz="0.0" izz="0.01"/>
    </inertial>
  </link>
  <transmission name="x_linear_actuator_trans">
    <type>transmission_interface/SimpleTransmission</type>
    <joint name="x_linear_actuator_joint">
      <hardwareInterface>hardware_interface/EffortJointInterface</hardwareInterface>
    </joint>
    <actuator name="x_linear_actuator_motor">
      <hardwareInterface>hardware_interface/EffortJointInterface</hardwareInterface>
    </actuator>
  </transmission>
  <transmission name="y_linear_actuator_trans">
    <type>transmission_interface/SimpleTransmission</type>
    <joint name="y_linear_actuator_joint">
      <hardwareInterface>hardware_interface/EffortJointInterface</hardwareInterface>
    </joint>
    <actuator name="y_linear_actuator_motor">
      <hardwareInterface>hardware_interface/EffortJointInterface</hardwareInterface>
    </actuator>
  </transmission>
  <transmission name="z_linear_actuator_trans">
    <type>transmission_interface/SimpleTransmission</type>
    <joint name="z_linear_actuator_joint">
      <hardwareInterface>hardware_interface/EffortJointInterface</hardwareInterface>
    </joint>
    <actuator name="z_linear_actuator_motor">
      <hardwareInterface>hardware_interface/EffortJointInterface</hardwareInterface>
    </actuator>
  </transmission>
  <transmission name="x_rotary_actuator_trans">
    <type>transmission_interface/SimpleTransmission</type>
    <joint name="x_rotary_actuator_joint">
      <hardwareInterface>hardware_interface/EffortJointInterface</hardwareInterface>
    </joint>
    <actuator name="x_rotary_actuator_motor">
      <hardwareInterface>hardware_interface/EffortJointInterface</hardwareInterface>
    </actuator>
  </transmission>
  <transmission name="y_rotary_actuator_trans">
    <type>transmission_interface/SimpleTransmission</type>
    <joint name="y_rotary_actuator_joint">
      <hardwareInterface>hardware_interface/EffortJointInterface</hardwareInterface>
    </joint>
    <actuator name="y_rotary_actuator_motor">
      <hardwareInterface>hardware_interface/EffortJointInterface</hardwareInterface>
    </actuator>
  </transmission>
  <transmission name="z_rotary_actuator_trans">
    <type>transmission_interface/SimpleTransmission</type>
    <joint name="z_rotary_actuator_joint">
      <hardwareInterface>hardware_interface/EffortJointInterface</hardwareInterface>
    </joint>
    <actuator name="z_rotary_actuator_motor">
      <hardwareInterface>hardware_interface/EffortJointInterface</hardwareInterface>
    </actuator>
  </transmission>
  <!-- =============== Gazebo =============== -->
  <gazebo>
    <plugin filename="libgazebo_ros_control.so" name="gazebo_ros_control">
      <robotNamespace>six_dof_cam</robotNamespace>
    </plugin>
  </gazebo>
  <gazebo reference="base_link">
    <!--<selfCollide>true</selfCollide>-->
    <mu1>0.05</mu1>
    <mu2>0.05</mu2>
  </gazebo>
  <gazebo reference="camera_link">
    <!--<selfCollide>true</selfCollide>-->
    <mu1>0.05</mu1>
    <mu2>0.05</mu2>
    <sensor name="stereo_camera" type="multicamera">
      <update_rate>30.0</update_rate>
      <camera name="left">
        <pose>0.05 0.03 0 0 0 0</pose>
        <horizontal_fov>1.91986217719</horizontal_fov>
        <image>
          <width>800</width>
          <height>800</height>
          <format>R8G8B8</format>
        </image>
        <clip>
          <near>0.05</near>
          <far>300</far>
        </clip>
        <noise>
          <type>gaussian</type>
          <mean>0.0</mean>
          <stddev>0.007</stddev>
        </noise>
      </camera>
      <camera name="right">
        <pose>0.05 -0.03 0 0 0 0</pose>
        <horizontal_fov>1.91986217719</horizontal_fov>
        <image>
          <width>800</width>
          <height>800</height>
          <format>R8G8B8</format>
        </image>
        <clip>
          <near>0.05</near>
          <far>300</far>
        </clip>
        <noise>
          <type>gaussian</type>
          <mean>0.0</mean>
          <stddev>0.007</stddev>
        </noise>
      </camera>
      <plugin filename="libgazebo_ros_multicamera.so" name="stereo_camera_controller">
        <alwaysOn>true</alwaysOn>
        <updateRate>0.0</updateRate>
        <cameraName>six_dof_cam/camera</cameraName>
        <imageTopicName>image_raw</imageTopicName>
        <cameraInfoTopicName>camera_info</cameraInfoTopicName>
        <frameName>camera_link</frameName>
        <!--<rightFrameName>right_camera_optical_frame</rightFrameName>-->
        <hackBaseline>0.07</hackBaseline>
        <distortionK1>0.0</distortionK1>
        <distortionK2>0.0</distortionK2>
        <distortionK3>0.0</distortionK3>
        <distortionT1>0.0</distortionT1>
        <distortionT2>0.0</distortionT2>
      </plugin>
    </sensor>
  </gazebo>
  <gazebo reference="x_rotary_actuator_link">
    <!-- <selfCollide>true</selfCollide> -->
    <mu1>0.05</mu1>
    <mu2>0.05</mu2>
  </gazebo>
  <gazebo reference="y_rotary_actuator_link">
    <!-- <selfCollide>true</selfCollide> -->
    <mu1>0.05</mu1>
    <mu2>0.05</mu2>
  </gazebo>
  <gazebo reference="z_rotary_actuator_link">
    <!-- <selfCollide>true</selfCollide> -->
    <mu1>0.05</mu1>
    <mu2>0.05</mu2>
  </gazebo>
  <gazebo reference="x_linear_actuator_link">
    <!-- <selfCollide>true</selfCollide> -->
    <mu1>0.05</mu1>
    <mu2>0.05</mu2>
  </gazebo>
  <gazebo reference="y_linear_actuator_link">
    <!-- <selfCollide>true</selfCollide> -->
    <mu1>0.05</mu1>
    <mu2>0.05</mu2>
  </gazebo>
  <gazebo reference="z_linear_actuator_link">
    <!-- <selfCollide>true</selfCollide> -->
    <mu1>0.05</mu1>
    <mu2>0.05</mu2>
  </gazebo>
</robot>

